<?xml version="1.0" ?>
<robot name="my_lidar" xmlns:xacro="http://ros.org/wiki/xacro">
  <xacro:include filename="$(find turtlebot3_description)/urdf/common_properties.xacro"/>
  <xacro:include filename="$(find dharmendra_model)/gazebo/my_lidar/my_lidar.gazebo.xacro"/>
  
  <link name= "base_footprint" />
  
  <joint name="base_joint" type="fixed">
    <parent link="base_footprint"/>
    <child link="my_lidar__link_0"/>
    <origin xyz="0.04061 -0.0922  -0.0155" rpy="1.5708 0     0"/>
  </joint>
  
  <joint name="my_lidar__link_0_right_link1_clone" type="revolute">
    <parent link="my_lidar__link_0"/>
    <child link="my_lidar__link_1_clone"/>
    <origin xyz="0.04061 -0.0922  -0.0155" rpy="1.5708 0     0"/>
    <axis xyz="0 0 1"/>
    <limit lower="-1.79769e+308" upper="1.79769e+308" effort="-1.0" velocity="-1.0"/>
  </joint>
  <joint name="my_lidar__link_0_left_link_1" type="revolute">
    <parent link="my_lidar__link_0"/>
    <child link="my_lidar__link_1"/>
    <origin xyz="0.04061  0.09259 -0.0155" rpy="1.5708 0     0"/>
    <axis xyz="0 0 1"/>
    <limit lower="-1.79769e+308" upper="1.79769e+308" effort="-1.0" velocity="-1.0"/>
  </joint>
  <joint name="my_lidar__link_0_caster_link_2" type="fixed">
    <parent link="my_lidar__link_0"/>
    <child link="my_lidar__link_2"/>
    <origin xyz="-0.11451  0.00097 -0.03299" rpy="0 0 0"/>
    <axis xyz="0 0 0"/>
    <limit lower="0" upper="0" effort="0" velocity="0"/>
  </joint>
  <joint name="my_lidar__link_0_lidar_link_3" type="fixed">
    <parent link="my_lidar__link_0"/>
    <child link="my_lidar__link_3"/>
    <origin xyz="0.05251 -0.00159  0.0545" rpy="0 0 0"/>
    <axis xyz="0 0 0"/>
    <limit lower="0" upper="0" effort="0" velocity="0"/>
  </joint>
  <link name="my_lidar__link_0">
    <inertial>
      <mass value="1"/>
      <origin xyz="0 0 0" rpy="0 0 0"/>
      <inertia ixx="0.166667" ixy="0" ixz="0" iyy="0.166667" iyz="0" izz="0.166667"/>
    </inertial>
    <collision name="my_lidar__collision">
      <origin xyz="-0.01922  0.00023  0.0095" rpy="0 0 0"/>
      <geometry>
        <box size="0.25 0.15 0.05"/>
      </geometry>
    </collision>
    <visual name="my_lidar__visual">
      <origin xyz="-0.01922  0.00023  0.0095" rpy="0 0 0"/>
      <geometry>
        <box size="0.25 0.15 0.05"/>
      </geometry>
    </visual>
  </link>
  <link name="my_lidar__link_1">
    <inertial>
      <mass value="1"/>
      <origin xyz="0 0 0" rpy="0 0 0"/>
      <inertia ixx="0.145833" ixy="0" ixz="0" iyy="0.145833" iyz="0" izz="0.125"/>
    </inertial>
    <collision name="my_lidar__collision">
      <origin xyz="0 0 0" rpy="0 0 0"/>
      <geometry>
        <cylinder radius="0.035" length="0.03"/>
      </geometry>
    </collision>
    <visual name="my_lidar__visual">
      <origin xyz="0 0 0" rpy="0 0 0"/>
      <geometry>
        <cylinder radius="0.035" length="0.03"/>
      </geometry>
    </visual>
  </link>
  <link name="my_lidar__link_1_clone">
    <inertial>
      <mass value="1"/>
      <origin xyz="0 0 0" rpy="0 0 0"/>
      <inertia ixx="0.145833" ixy="0" ixz="0" iyy="0.145833" iyz="0" izz="0.125"/>
    </inertial>
    <collision name="my_lidar__collision">
      <origin xyz="0 0 0" rpy="0 0 0"/>
      <geometry>
        <cylinder radius="0.035" length="0.03"/>
      </geometry>
    </collision>
    <visual name="my_lidar__visual">
      <origin xyz="0 0 0" rpy="0 0 0"/>
      <geometry>
        <cylinder radius="0.035" length="0.03"/>
      </geometry>
    </visual>
  </link>
  <link name="my_lidar__link_2">
    <inertial>
      <mass value="1"/>
      <origin xyz="0 0 0" rpy="0 0 0"/>
      <inertia ixx="0.1" ixy="0" ixz="0" iyy="0.1" iyz="0" izz="0.1"/>
    </inertial>
    <collision name="my_lidar__collision">
      <origin xyz="0 0 0" rpy="0 0 0"/>
      <geometry>
        <sphere radius="0.0175"/>
      </geometry>
    </collision>
    <visual name="my_lidar__visual">
      <origin xyz="0 0 0" rpy="0 0 0"/>
      <geometry>
        <sphere radius="0.0175"/>
      </geometry>
    </visual>
  </link>
  <link name="my_lidar__link_3">
    <inertial>
      <mass value="1"/>
      <origin xyz="0 0 0" rpy="0 0 0"/>
      <inertia ixx="0.145833" ixy="0" ixz="0" iyy="0.145833" iyz="0" izz="0.125"/>
    </inertial>
    <collision name="my_lidar__collision">
      <origin xyz="0 0 0" rpy="0 0 0"/>
      <geometry>
        <cylinder radius="0.05" length="0.05"/>
      </geometry>
    </collision>
    <visual name="my_lidar__visual">
      <origin xyz="0 0 0" rpy="0 0 0"/>
      <geometry>
        <cylinder radius="0.05" length="0.05"/>
      </geometry>
    </visual>
  </link>
</robot>
