<?xml version="1.0" ?>
<robot name="bfl_6" xmlns:xacro="http://ros.org/wiki/xacro">
  <xacro:include filename="$(find turtlebot3_description)/urdf/common_properties.xacro"/>
  <xacro:include filename="$(find dharmendra_model)/gazebo/bfl_6/bfl_6.gazebo"/>

  <link name= "base_footprint" />
  
  <joint name="base_joint" type="fixed">
    <parent link="base_footprint"/>
    <child link="bfl_6__link_1"/>
    <origin xyz="0.04061 -0.0922  -0.0155" rpy="0 0 0"/>
  </joint>
  
  <link name="bfl_6__link_1">
    <inertial>
      <mass value="13"/>
      <origin xyz="0 0 0" rpy="0 0 0"/>
      <inertia ixx="0.126294" ixy="0" ixz="0" iyy="0.0334995" iyz="0" izz="0.157301"/>
    </inertial>
    <collision name="bfl_6__collision">
      <origin xyz="-0.02259 -0.0007   0.0075" rpy="0 0 0"/>
      <geometry>
        <box size="0.25 0.15 0.05"/>
      </geometry>
    </collision>
    <visual name="bfl_6__visual">
      <origin xyz="-0.02259 -0.0007   0.0075" rpy="0 0 0"/>
      <geometry>
        <box size="0.25 0.15 0.05"/>
      </geometry>
    </visual>
  </link>
  
  
  <joint name="bfl_6__link_1_left_wheel" type="continuous">
    <parent link="bfl_6__link_1"/>
    <child link="bfl_6__link_4"/>
    <origin xyz="0.05496  0.09169 -0.0175" rpy="1.5708 0     0"/>
    <axis xyz="0 0 1"/>
    <limit lower="-1.79769e+308" upper="1.79769e+308" effort="-1.0" velocity="-1.0"/>
  </joint>
  
  <link name="bfl_6__link_4">
    <inertial>
      <mass value="2.8498940e-02"/>
      <origin xyz="0 0 0" rpy="0 0 0"/>
      <inertia ixx="0.145833" ixy="0" ixz="0" iyy="0.145833" iyz="0" izz="0.125"/>
    </inertial>
    <collision name="bfl_6__collision">
      <origin xyz="0 0 0" rpy="0 0 0"/>
      <geometry>
        <cylinder radius="0.035" length="0.03"/>
      </geometry>
    </collision>
    <visual name="bfl_6__visual">
      <origin xyz="0 0 0" rpy="0 0 0"/>
      <geometry>
        <cylinder radius="0.035" length="0.03"/>
      </geometry>
    </visual>
  </link>
  
  
  <joint name="bfl_6__link_1_right_wheel" type="continuous">
    <parent link="bfl_6__link_1"/>
    <child link="bfl_6__link_4_clone"/>
    <origin xyz="0.05496 -0.0936  -0.0175" rpy="1.5708 0     0"/>
    <axis xyz="0 0 1"/>
    <limit lower="-1.79769e+308" upper="1.79769e+308" effort="-1.0" velocity="-1.0"/>
  </joint>
  
  <link name="bfl_6__link_4_clone">
    <inertial>
      <mass value="2.8498940e-02"/>
      <origin xyz="0 0 0" rpy="0 0 0"/>
      <inertia ixx="0.145833" ixy="0" ixz="0" iyy="0.145833" iyz="0" izz="0.125"/>
    </inertial>
    <collision name="bfl_6__collision">
      <origin xyz="0 0 0" rpy="0 0 0"/>
      <geometry>
        <cylinder radius="0.035" length="0.03"/>
      </geometry>
    </collision>
    <visual name="bfl_6__visual">
      <origin xyz="0 0 0" rpy="0 0 0"/>
      <geometry>
        <cylinder radius="0.035" length="0.03"/>
      </geometry>
    </visual>
  </link>
  
  
  <joint name="bfl_6__link_1_castor_wheel" type="fixed">
    <parent link="bfl_6__link_1"/>
    <child link="bfl_6__link_5"/>
    <origin xyz="-0.1223   0.00071 -0.035" rpy="0 0 0"/>
    <axis xyz="0 0 0"/>
    <limit lower="0" upper="0" effort="0" velocity="0"/>
  </joint>
  
  <link name="bfl_6__link_5">
    <inertial>
      <mass value="0.005"/>
      <origin xyz="0 0 0" rpy="0 0 0"/>
      <inertia ixx="0.1" ixy="0" ixz="0" iyy="0.1" iyz="0" izz="0.1"/>
    </inertial>
    <collision name="bfl_6__collision">
      <origin xyz="0 0 0" rpy="0 0 0"/>
      <geometry>
        <sphere radius="0.0175"/>
      </geometry>
    </collision>
  </link>
  
  
  <joint name="bfl_6__link_1_lidar" type="fixed">
    <parent link="bfl_6__link_1"/>
    <child link="bfl_6__link_6"/>
    <origin xyz="0.03496 0.00189 0.0625" rpy="0 0 0"/>
    <axis xyz="0 0 0"/>
    <limit lower="0" upper="0" effort="0" velocity="0"/>
  </joint>
  
  <link name="bfl_6__link_6">
    <inertial>
      <mass value="0.114"/>
      <origin xyz="0 0 0" rpy="0 0 0"/>
      <inertia ixx="0.145833" ixy="0" ixz="0" iyy="0.145833" iyz="0" izz="0.125"/>
    </inertial>
    <collision name="bfl_6__collision">
      <origin xyz="0 0 0" rpy="0 0 0"/>
      <geometry>
        <cylinder radius="0.05" length="0.06"/>
      </geometry>
    </collision>
    <visual name="bfl_6__visual">
      <origin xyz="0 0 0" rpy="0 0 0"/>
      <geometry>
        <cylinder radius="0.05" length="0.06"/>
      </geometry>
    </visual>
  </link>
  
  
</robot>
