<?xml version='1.0'?>
<sdf version='1.5'>
  <model name='bfl_14'>
    <link name='base_link'>
      <inertial>
        <pose>0.009108 0 -0.033726 0 -0 0</pose>
        <mass>1.01774</mass>
        <inertia>
          <ixx>0.00123679</ixx>
          <ixy>4.78648e-20</ixy>
          <ixz>-3.11721e-05</ixz>
          <iyy>0.00293732</iyy>
          <iyz>1.98612e-20</iyz>
          <izz>0.00365409</izz>
        </inertia>
      </inertial>
      <self_collide>0</self_collide>
      <enable_wind>0</enable_wind>
      <kinematic>0</kinematic>
      <pose>0 0 0 0 -0 0</pose>
      <visual name='base_link_visual'>
        <pose>0 0 0 0 -0 0</pose>
        <geometry>
          <mesh>
            <scale>1 1 1</scale>
            <uri>/home/bfl/catkin_ws/src/full_tesla_truck_urdf/meshes/base_link.STL</uri>
          </mesh>
        </geometry>
        <material>
          <shader type='pixel'/>
          <emissive>0 0 0 1</emissive>
        </material>
        <transparency>0</transparency>
        <cast_shadows>1</cast_shadows>
      </visual>
      <collision name='base_link_collision'>
        <laser_retro>0</laser_retro>
        <max_contacts>10</max_contacts>
        <pose>0 0 0 0 -0 0</pose>
        <geometry>
          <mesh>
            <uri>/home/bfl/catkin_ws/src/full_tesla_truck_urdf/meshes/base_link.STL</uri>
            <scale>1 1 1</scale>
          </mesh>
        </geometry>
        <surface>
          <friction>
            <ode>
              <mu>1</mu>
              <mu2>1</mu2>
              <fdir1>0 0 0</fdir1>
              <slip1>0</slip1>
              <slip2>0</slip2>
            </ode>
            <torsional>
              <coefficient>1</coefficient>
              <patch_radius>0</patch_radius>
              <surface_radius>0</surface_radius>
              <use_patch_radius>1</use_patch_radius>
              <ode>
                <slip>0</slip>
              </ode>
            </torsional>
          </friction>
          <bounce>
            <restitution_coefficient>0</restitution_coefficient>
            <threshold>1e+06</threshold>
          </bounce>
          <contact>
            <collide_without_contact>0</collide_without_contact>
            <collide_without_contact_bitmask>1</collide_without_contact_bitmask>
            <collide_bitmask>1</collide_bitmask>
            <ode>
              <soft_cfm>0</soft_cfm>
              <soft_erp>0.2</soft_erp>
              <kp>1e+13</kp>
              <kd>1</kd>
              <max_vel>0.01</max_vel>
              <min_depth>0</min_depth>
            </ode>
            <bullet>
              <split_impulse>1</split_impulse>
              <split_impulse_penetration_threshold>-0.01</split_impulse_penetration_threshold>
              <soft_cfm>0</soft_cfm>
              <soft_erp>0.2</soft_erp>
              <kp>1e+13</kp>
              <kd>1</kd>
            </bullet>
          </contact>
        </surface>
      </collision>
    </link>
    <link name='back_left_link'>
      <pose>-0.049669 0.054511 -0.056567 0 -0 0</pose>
      <inertial>
        <pose>0 -0.005 0 0 -0 0</pose>
        <mass>0.0066289</mass>
        <inertia>
          <ixx>4.3359e-07</ixx>
          <ixy>1.1029e-24</ixy>
          <ixz>2.93e-23</ixz>
          <iyy>7.6063e-07</iyy>
          <iyz>-1.7922e-24</iyz>
          <izz>4.3359e-07</izz>
        </inertia>
      </inertial>
      <self_collide>0</self_collide>
      <enable_wind>0</enable_wind>
      <kinematic>0</kinematic>
      <visual name='back_left_link_visual'>
        <pose>0 0 0 0 -0 0</pose>
        <geometry>
          <mesh>
            <scale>1 1 1</scale>
            <uri>/home/bfl/catkin_ws/src/full_tesla_truck_urdf/meshes/back_left_link.STL</uri>
          </mesh>
        </geometry>
        <material>
          <shader type='pixel'/>
        </material>
        <transparency>0</transparency>
        <cast_shadows>1</cast_shadows>
      </visual>
      <collision name='back_left_link_collision'>
        <laser_retro>0</laser_retro>
        <max_contacts>10</max_contacts>
        <pose>0 0 0 0 -0 0</pose>
        <geometry>
          <mesh>
            <uri>/home/bfl/catkin_ws/src/full_tesla_truck_urdf/meshes/back_left_link.STL</uri>
            <scale>1 1 1</scale>
          </mesh>
        </geometry>
        <surface>
          <friction>
            <ode>
              <mu>1</mu>
              <mu2>1</mu2>
              <fdir1>0 0 0</fdir1>
              <slip1>0</slip1>
              <slip2>0</slip2>
            </ode>
            <torsional>
              <coefficient>1</coefficient>
              <patch_radius>0</patch_radius>
              <surface_radius>0</surface_radius>
              <use_patch_radius>1</use_patch_radius>
              <ode>
                <slip>0</slip>
              </ode>
            </torsional>
          </friction>
          <bounce>
            <restitution_coefficient>0</restitution_coefficient>
            <threshold>1e+06</threshold>
          </bounce>
          <contact>
            <collide_without_contact>0</collide_without_contact>
            <collide_without_contact_bitmask>1</collide_without_contact_bitmask>
            <collide_bitmask>1</collide_bitmask>
            <ode>
              <soft_cfm>0</soft_cfm>
              <soft_erp>0.2</soft_erp>
              <kp>1e+13</kp>
              <kd>1</kd>
              <max_vel>0.01</max_vel>
              <min_depth>0</min_depth>
            </ode>
            <bullet>
              <split_impulse>1</split_impulse>
              <split_impulse_penetration_threshold>-0.01</split_impulse_penetration_threshold>
              <soft_cfm>0</soft_cfm>
              <soft_erp>0.2</soft_erp>
              <kp>1e+13</kp>
              <kd>1</kd>
            </bullet>
          </contact>
        </surface>
      </collision>
    </link>
    <link name='back_right_link'>
      <pose>-0.049669 -0.054464 -0.056567 0 -0 0</pose>
      <inertial>
        <pose>0 0.005 0 0 -0 0</pose>
        <mass>0.0066289</mass>
        <inertia>
          <ixx>4.3359e-07</ixx>
          <ixy>-3.108e-24</ixy>
          <ixz>-2.4808e-23</ixz>
          <iyy>7.6063e-07</iyy>
          <iyz>-1.6326e-24</iyz>
          <izz>4.3359e-07</izz>
        </inertia>
      </inertial>
      <self_collide>0</self_collide>
      <enable_wind>0</enable_wind>
      <kinematic>0</kinematic>
      <visual name='back_right_link_visual'>
        <pose>0 0 0 0 -0 0</pose>
        <geometry>
          <mesh>
            <scale>1 1 1</scale>
            <uri>/home/bfl/catkin_ws/src/full_tesla_truck_urdf/meshes/back_right_link.STL</uri>
          </mesh>
        </geometry>
        <material>
          <shader type='pixel'/>
        </material>
        <transparency>0</transparency>
        <cast_shadows>1</cast_shadows>
      </visual>
      <collision name='back_right_link_collision'>
        <laser_retro>0</laser_retro>
        <max_contacts>10</max_contacts>
        <pose>0 0 0 0 -0 0</pose>
        <geometry>
          <mesh>
            <uri>/home/bfl/catkin_ws/src/full_tesla_truck_urdf/meshes/back_right_link.STL</uri>
            <scale>1 1 1</scale>
          </mesh>
        </geometry>
        <surface>
          <friction>
            <ode>
              <mu>1</mu>
              <mu2>1</mu2>
              <fdir1>0 0 0</fdir1>
              <slip1>0</slip1>
              <slip2>0</slip2>
            </ode>
            <torsional>
              <coefficient>1</coefficient>
              <patch_radius>0</patch_radius>
              <surface_radius>0</surface_radius>
              <use_patch_radius>1</use_patch_radius>
              <ode>
                <slip>0</slip>
              </ode>
            </torsional>
          </friction>
          <bounce>
            <restitution_coefficient>0</restitution_coefficient>
            <threshold>1e+06</threshold>
          </bounce>
          <contact>
            <collide_without_contact>0</collide_without_contact>
            <collide_without_contact_bitmask>1</collide_without_contact_bitmask>
            <collide_bitmask>1</collide_bitmask>
            <ode>
              <soft_cfm>0</soft_cfm>
              <soft_erp>0.2</soft_erp>
              <kp>1e+13</kp>
              <kd>1</kd>
              <max_vel>0.01</max_vel>
              <min_depth>0</min_depth>
            </ode>
            <bullet>
              <split_impulse>1</split_impulse>
              <split_impulse_penetration_threshold>-0.01</split_impulse_penetration_threshold>
              <soft_cfm>0</soft_cfm>
              <soft_erp>0.2</soft_erp>
              <kp>1e+13</kp>
              <kd>1</kd>
            </bullet>
          </contact>
        </surface>
      </collision>
    </link>
    <link name='front_left_link'>
      <pose>0.06153 0.054495 -0.056567 0 -0 0</pose>
      <inertial>
        <pose>0 -0.005 0 0 -0 0</pose>
        <mass>0.0066289</mass>
        <inertia>
          <ixx>4.3359e-07</ixx>
          <ixy>-2.7573e-25</ixy>
          <ixz>5.076e-23</ixz>
          <iyy>7.6063e-07</iyy>
          <iyz>4.1359e-24</iyz>
          <izz>4.3359e-07</izz>
        </inertia>
      </inertial>
      <self_collide>0</self_collide>
      <enable_wind>0</enable_wind>
      <kinematic>0</kinematic>
      <visual name='front_left_link_visual'>
        <pose>0 0 0 0 -0 0</pose>
        <geometry>
          <mesh>
            <scale>1 1 1</scale>
            <uri>/home/bfl/catkin_ws/src/full_tesla_truck_urdf/meshes/front_left_link.STL</uri>
          </mesh>
        </geometry>
        <material>
          <shader type='pixel'/>
        </material>
        <transparency>0</transparency>
        <cast_shadows>1</cast_shadows>
      </visual>
      <collision name='front_left_link_collision'>
        <laser_retro>0</laser_retro>
        <max_contacts>10</max_contacts>
        <pose>0 0 0 0 -0 0</pose>
        <geometry>
          <mesh>
            <uri>/home/bfl/catkin_ws/src/full_tesla_truck_urdf/meshes/front_left_link.STL</uri>
            <scale>1 1 1</scale>
          </mesh>
        </geometry>
        <surface>
          <friction>
            <ode>
              <mu>1</mu>
              <mu2>1</mu2>
              <fdir1>0 0 0</fdir1>
              <slip1>0</slip1>
              <slip2>0</slip2>
            </ode>
            <torsional>
              <coefficient>1</coefficient>
              <patch_radius>0</patch_radius>
              <surface_radius>0</surface_radius>
              <use_patch_radius>1</use_patch_radius>
              <ode>
                <slip>0</slip>
              </ode>
            </torsional>
          </friction>
          <bounce>
            <restitution_coefficient>0</restitution_coefficient>
            <threshold>1e+06</threshold>
          </bounce>
          <contact>
            <collide_without_contact>0</collide_without_contact>
            <collide_without_contact_bitmask>1</collide_without_contact_bitmask>
            <collide_bitmask>1</collide_bitmask>
            <ode>
              <soft_cfm>0</soft_cfm>
              <soft_erp>0.2</soft_erp>
              <kp>1e+13</kp>
              <kd>1</kd>
              <max_vel>0.01</max_vel>
              <min_depth>0</min_depth>
            </ode>
            <bullet>
              <split_impulse>1</split_impulse>
              <split_impulse_penetration_threshold>-0.01</split_impulse_penetration_threshold>
              <soft_cfm>0</soft_cfm>
              <soft_erp>0.2</soft_erp>
              <kp>1e+13</kp>
              <kd>1</kd>
            </bullet>
          </contact>
        </surface>
      </collision>
    </link>
    <link name='front_right_link'>
      <pose>0.06153 -0.054505 -0.056567 0 -0 0</pose>
      <inertial>
        <pose>0 0.005 0 0 -0 0</pose>
        <mass>0.0066289</mass>
        <inertia>
          <ixx>4.3359e-07</ixx>
          <ixy>-2.8345e-24</ixy>
          <ixz>5.0785e-24</ixz>
          <iyy>7.6063e-07</iyy>
          <iyz>-1.8072e-24</iyz>
          <izz>4.3359e-07</izz>
        </inertia>
      </inertial>
      <self_collide>0</self_collide>
      <enable_wind>0</enable_wind>
      <kinematic>0</kinematic>
      <visual name='front_right_link_visual'>
        <pose>0 0 0 0 -0 0</pose>
        <geometry>
          <mesh>
            <scale>1 1 1</scale>
            <uri>/home/bfl/catkin_ws/src/full_tesla_truck_urdf/meshes/front_right_link.STL</uri>
          </mesh>
        </geometry>
        <material>
          <shader type='pixel'/>
        </material>
        <transparency>0</transparency>
        <cast_shadows>1</cast_shadows>
      </visual>
      <collision name='front_right_link_collision'>
        <laser_retro>0</laser_retro>
        <max_contacts>10</max_contacts>
        <pose>0 0 0 0 -0 0</pose>
        <geometry>
          <mesh>
            <uri>/home/bfl/catkin_ws/src/full_tesla_truck_urdf/meshes/front_right_link.STL</uri>
            <scale>1 1 1</scale>
          </mesh>
        </geometry>
        <surface>
          <friction>
            <ode>
              <mu>1</mu>
              <mu2>1</mu2>
              <fdir1>0 0 0</fdir1>
              <slip1>0</slip1>
              <slip2>0</slip2>
            </ode>
            <torsional>
              <coefficient>1</coefficient>
              <patch_radius>0</patch_radius>
              <surface_radius>0</surface_radius>
              <use_patch_radius>1</use_patch_radius>
              <ode>
                <slip>0</slip>
              </ode>
            </torsional>
          </friction>
          <bounce>
            <restitution_coefficient>0</restitution_coefficient>
            <threshold>1e+06</threshold>
          </bounce>
          <contact>
            <collide_without_contact>0</collide_without_contact>
            <collide_without_contact_bitmask>1</collide_without_contact_bitmask>
            <collide_bitmask>1</collide_bitmask>
            <ode>
              <soft_cfm>0</soft_cfm>
              <soft_erp>0.2</soft_erp>
              <kp>1e+13</kp>
              <kd>1</kd>
              <max_vel>0.01</max_vel>
              <min_depth>0</min_depth>
            </ode>
            <bullet>
              <split_impulse>1</split_impulse>
              <split_impulse_penetration_threshold>-0.01</split_impulse_penetration_threshold>
              <soft_cfm>0</soft_cfm>
              <soft_erp>0.2</soft_erp>
              <kp>1e+13</kp>
              <kd>1</kd>
            </bullet>
          </contact>
        </surface>
      </collision>
    </link>
    <link name='link_0'>
      <inertial>
        <mass>1</mass>
        <inertia>
          <ixx>0.145833</ixx>
          <ixy>0</ixy>
          <ixz>0</ixz>
          <iyy>0.145833</iyy>
          <iyz>0</iyz>
          <izz>0.125</izz>
        </inertia>
        <pose>0 0 0 0 -0 0</pose>
      </inertial>
      <pose>0.001446 -0.000805 0.008219 -3.1e-05 -8.2e-05 -0.307271</pose>
      <gravity>1</gravity>
      <self_collide>0</self_collide>
      <kinematic>0</kinematic>
      <enable_wind>0</enable_wind>
      <visual name='visual'>
        <pose>0 0 0 0 -0 0</pose>
        <geometry>
          <cylinder>
            <radius>0.03</radius>
            <length>0.015</length>
          </cylinder>
        </geometry>
        <material>
          <lighting>1</lighting>
          <script>
            <uri>file://media/materials/scripts/gazebo.material</uri>
            <name>Gazebo/Grey</name>
          </script>
          <shader type='pixel'>
            <normal_map>__default__</normal_map>
          </shader>
          <ambient>0.3 0.3 0.3 1</ambient>
          <diffuse>0.7 0.7 0.7 1</diffuse>
          <specular>0.01 0.01 0.01 1</specular>
          <emissive>0 0 0 1</emissive>
        </material>
        <transparency>0</transparency>
        <cast_shadows>1</cast_shadows>
      </visual>
      <collision name='collision'>
        <laser_retro>0</laser_retro>
        <max_contacts>10</max_contacts>
        <pose>0 0 0 0 -0 0</pose>
        <geometry>
          <cylinder>
            <radius>0.03</radius>
            <length>0.015</length>
          </cylinder>
        </geometry>
        <surface>
          <friction>
            <ode>
              <mu>1</mu>
              <mu2>1</mu2>
              <fdir1>0 0 0</fdir1>
              <slip1>0</slip1>
              <slip2>0</slip2>
            </ode>
            <torsional>
              <coefficient>1</coefficient>
              <patch_radius>0</patch_radius>
              <surface_radius>0</surface_radius>
              <use_patch_radius>1</use_patch_radius>
              <ode>
                <slip>0</slip>
              </ode>
            </torsional>
          </friction>
          <bounce>
            <restitution_coefficient>0</restitution_coefficient>
            <threshold>1e+06</threshold>
          </bounce>
          <contact>
            <collide_without_contact>0</collide_without_contact>
            <collide_without_contact_bitmask>1</collide_without_contact_bitmask>
            <collide_bitmask>1</collide_bitmask>
            <ode>
              <soft_cfm>0</soft_cfm>
              <soft_erp>0.2</soft_erp>
              <kp>1e+13</kp>
              <kd>1</kd>
              <max_vel>0.01</max_vel>
              <min_depth>0</min_depth>
            </ode>
            <bullet>
              <split_impulse>1</split_impulse>
              <split_impulse_penetration_threshold>-0.01</split_impulse_penetration_threshold>
              <soft_cfm>0</soft_cfm>
              <soft_erp>0.2</soft_erp>
              <kp>1e+13</kp>
              <kd>1</kd>
            </bullet>
          </contact>
        </surface>
      </collision>
    </link>
    <link name='link_1'>
      <inertial>
        <mass>1</mass>
        <inertia>
          <ixx>0.166667</ixx>
          <ixy>0</ixy>
          <ixz>0</ixz>
          <iyy>0.166667</iyy>
          <iyz>0</iyz>
          <izz>0.166667</izz>
        </inertia>
        <pose>0 0 0 0 -0 0</pose>
      </inertial>
      <pose>-0.099965 0.000523 -0.037493 -5.8e-05 -6.6e-05 0.057909</pose>
      <gravity>1</gravity>
      <self_collide>0</self_collide>
      <kinematic>0</kinematic>
      <enable_wind>0</enable_wind>
      <visual name='visual'>
        <pose>0 0 0 0 -0 0</pose>
        <geometry>
          <box>
            <size>0.01 0.01 0.01</size>
          </box>
        </geometry>
        <material>
          <lighting>1</lighting>
          <script>
            <uri>file://media/materials/scripts/gazebo.material</uri>
            <name>Gazebo/Grey</name>
          </script>
          <shader type='pixel'>
            <normal_map>__default__</normal_map>
          </shader>
          <ambient>0.3 0.3 0.3 1</ambient>
          <diffuse>0.7 0.7 0.7 1</diffuse>
          <specular>0.01 0.01 0.01 1</specular>
          <emissive>0 0 0 1</emissive>
        </material>
        <transparency>0</transparency>
        <cast_shadows>1</cast_shadows>
      </visual>
      <collision name='collision'>
        <laser_retro>0</laser_retro>
        <max_contacts>10</max_contacts>
        <pose>0 0 0 0 -0 0</pose>
        <geometry>
          <box>
            <size>0.01 0.01 0.01</size>
          </box>
        </geometry>
        <surface>
          <friction>
            <ode>
              <mu>1</mu>
              <mu2>1</mu2>
              <fdir1>0 0 0</fdir1>
              <slip1>0</slip1>
              <slip2>0</slip2>
            </ode>
            <torsional>
              <coefficient>1</coefficient>
              <patch_radius>0</patch_radius>
              <surface_radius>0</surface_radius>
              <use_patch_radius>1</use_patch_radius>
              <ode>
                <slip>0</slip>
              </ode>
            </torsional>
          </friction>
          <bounce>
            <restitution_coefficient>0</restitution_coefficient>
            <threshold>1e+06</threshold>
          </bounce>
          <contact>
            <collide_without_contact>0</collide_without_contact>
            <collide_without_contact_bitmask>1</collide_without_contact_bitmask>
            <collide_bitmask>1</collide_bitmask>
            <ode>
              <soft_cfm>0</soft_cfm>
              <soft_erp>0.2</soft_erp>
              <kp>1e+13</kp>
              <kd>1</kd>
              <max_vel>0.01</max_vel>
              <min_depth>0</min_depth>
            </ode>
            <bullet>
              <split_impulse>1</split_impulse>
              <split_impulse_penetration_threshold>-0.01</split_impulse_penetration_threshold>
              <soft_cfm>0</soft_cfm>
              <soft_erp>0.2</soft_erp>
              <kp>1e+13</kp>
              <kd>1</kd>
            </bullet>
          </contact>
        </surface>
      </collision>
    </link>
    <joint name='back_left_joint' type='revolute'>
      <parent>base_link</parent>
      <child>back_left_link</child>
      <pose>0 0 0 0 -0 0</pose>
      <axis>
        <xyz>0 -1 0</xyz>
        <limit>
          <lower>-1e+16</lower>
          <upper>1e+16</upper>
          <effort>0</effort>
          <velocity>0</velocity>
        </limit>
        <dynamics>
          <spring_reference>0</spring_reference>
          <spring_stiffness>0</spring_stiffness>
          <damping>0</damping>
          <friction>0</friction>
        </dynamics>
      </axis>
      <physics>
        <ode>
          <limit>
            <cfm>0</cfm>
            <erp>0.2</erp>
          </limit>
          <suspension>
            <cfm>0</cfm>
            <erp>0.2</erp>
          </suspension>
        </ode>
      </physics>
    </joint>
    <joint name='back_right_joint' type='revolute'>
      <parent>base_link</parent>
      <child>back_right_link</child>
      <pose>0 0 0 0 -0 0</pose>
      <axis>
        <xyz>0 1 0</xyz>
        <limit>
          <lower>-1e+16</lower>
          <upper>1e+16</upper>
          <effort>0</effort>
          <velocity>0</velocity>
        </limit>
        <dynamics>
          <spring_reference>0</spring_reference>
          <spring_stiffness>0</spring_stiffness>
          <damping>0</damping>
          <friction>0</friction>
        </dynamics>
      </axis>
      <physics>
        <ode>
          <limit>
            <cfm>0</cfm>
            <erp>0.2</erp>
          </limit>
          <suspension>
            <cfm>0</cfm>
            <erp>0.2</erp>
          </suspension>
        </ode>
      </physics>
    </joint>
    <joint name='lidar_joint' type='fixed'>
      <parent>base_link</parent>
      <child>link_0</child>
      <pose>0 0 0 0 -0 0</pose>
      <physics>
        <ode>
          <limit>
            <cfm>0</cfm>
            <erp>0.2</erp>
          </limit>
          <suspension>
            <cfm>0</cfm>
            <erp>0.2</erp>
          </suspension>
        </ode>
      </physics>
    </joint>
    <joint name='camera_joint' type='fixed'>
      <parent>base_link</parent>
      <child>link_1</child>
      <pose>0 0 0 0 -0 0</pose>
      <physics>
        <ode>
          <limit>
            <cfm>0</cfm>
            <erp>0.2</erp>
          </limit>
          <suspension>
            <cfm>0</cfm>
            <erp>0.2</erp>
          </suspension>
        </ode>
      </physics>
    </joint>
    <joint name='front_left_joint' type='revolute'>
      <parent>base_link</parent>
      <child>front_left_link</child>
      <pose>0 0 0 0 -0 0</pose>
      <axis>
        <xyz>0 -1 0</xyz>
        <limit>
          <lower>-1e+16</lower>
          <upper>1e+16</upper>
          <effort>0</effort>
          <velocity>0</velocity>
        </limit>
        <dynamics>
          <spring_reference>0</spring_reference>
          <spring_stiffness>0</spring_stiffness>
          <damping>0</damping>
          <friction>0</friction>
        </dynamics>
      </axis>
      <physics>
        <ode>
          <limit>
            <cfm>0</cfm>
            <erp>0.2</erp>
          </limit>
          <suspension>
            <cfm>0</cfm>
            <erp>0.2</erp>
          </suspension>
        </ode>
      </physics>
    </joint>
    <joint name='front_right_joint' type='revolute'>
      <parent>base_link</parent>
      <child>front_right_link</child>
      <pose>0 0 0 0 -0 0</pose>
      <axis>
        <xyz>0 1 0</xyz>
        <limit>
          <lower>-1e+16</lower>
          <upper>1e+16</upper>
          <effort>0</effort>
          <velocity>0</velocity>
        </limit>
        <dynamics>
          <spring_reference>0</spring_reference>
          <spring_stiffness>0</spring_stiffness>
          <damping>0</damping>
          <friction>0</friction>
        </dynamics>
      </axis>
      <physics>
        <ode>
          <limit>
            <cfm>0</cfm>
            <erp>0.2</erp>
          </limit>
          <suspension>
            <cfm>0</cfm>
            <erp>0.2</erp>
          </suspension>
        </ode>
      </physics>
    </joint>
    <static>0</static>
    <allow_auto_disable>1</allow_auto_disable>
  </model>
</sdf>
