<?xml version="1.0" ?>
<robot name="bfl_9" xmlns:xacro="http://ros.org/wiki/xacro">
  <xacro:include filename="$(find dharmendra_model)/gazebo/bfl_9/bfl_9.gazebo"/>
  
  <!--link name= "base_footprint" /> 
 
  <joint name="base_joint" type="fixed">
    <parent link="base_footprint"/>
    <child link="chassy_link"/>
    <origin xyz="0 0  0" rpy="0 0 0"/>
  </joint-->
  
  <joint name="camera_joint" type="fixed">
    <parent link="chassy_link"/>
    <child link="camera_link"/>
    <origin xyz="-0.08272  0.00202  0.09503" rpy="0.0 0.0    0.0"/>
    <axis xyz="0 0 0"/>
    <limit lower="0" upper="0" effort="0" velocity="0"/>
  </joint>
  
  <link name="camera_link">
    <inertial>
      <mass value="1"/>
      <origin xyz="0 0 0" rpy="0 0 0"/>
      <inertia ixx="0.166667" ixy="0" ixz="0" iyy="0.166667" iyz="0" izz="0.166667"/>
    </inertial>
    <collision>
      <origin xyz="0 0 0" rpy="0 0 0"/>
      <geometry>
        <box size="0.07071 0.03 0.03"/>
      </geometry>
    </collision>
    <visual>
      <origin xyz="0 0 0" rpy="0 0 0"/>
      <geometry>
        <box size="0.07071 0.03 0.03"/>
      </geometry>
    </visual>
  </link>
  
  
  <joint name="back_left_joint" type="revolute">
    <parent link="chassy_link"/>
    <child link="back_left_link"/>
    <origin xyz="0.06435 -0.09418 -0.015" rpy="1.5708 0     0"/>
    <axis xyz="0 0 1"/>
    <limit lower="-1.79769e+308" upper="1.79769e+308" effort="-1.0" velocity="-1.0"/>
  </joint>
  
  <link name="back_left_link">
    <inertial>
      <mass value="1"/>
      <origin xyz="0 0 0" rpy="0 0 0"/>
      <inertia ixx="0.145833" ixy="0" ixz="0" iyy="0.145833" iyz="0" izz="0.125"/>
    </inertial>
    <collision>
      <origin xyz="0 0 0" rpy="0 0 0"/>
      <geometry>
        <cylinder radius="0.04" length="0.03"/>
      </geometry>
    </collision>
    <visual>
      <origin xyz="0 0 0" rpy="0 0 0"/>
      <geometry>
        <cylinder radius="0.04" length="0.03"/>
      </geometry>
    </visual>
  </link>
  
  
  <joint name="back_right_joint" type="revolute">
    <parent link="chassy_link"/>
    <child link="back_right_link"/>
    <origin xyz="0.06435  0.09414 -0.015" rpy="1.5708 0     0"/>
    <axis xyz="0 0 1"/>
    <limit lower="-1.79769e+308" upper="1.79769e+308" effort="-1.0" velocity="-1.0"/>
  </joint>
  
  <link name="back_right_link">
    <inertial>
      <mass value="1"/>
      <origin xyz="0 0 0" rpy="0 0 0"/>
      <inertia ixx="0.145833" ixy="0" ixz="0" iyy="0.145833" iyz="0" izz="0.125"/>
    </inertial>
    <collision>
      <origin xyz="0 0 0" rpy="0 0 0"/>
      <geometry>
        <cylinder radius="0.04" length="0.03"/>
      </geometry>
    </collision>
    <visual>
      <origin xyz="0 0 0" rpy="0 0 0"/>
      <geometry>
        <cylinder radius="0.04" length="0.03"/>
      </geometry>
    </visual>
  </link>
  
  
  <joint name="front_right_joint" type="revolute">
    <parent link="chassy_link"/>
    <child link="front_right_link"/>
    <origin xyz="-0.09187  0.09414 -0.015" rpy="1.5708 0     0"/>
    <axis xyz="0 0 1"/>
    <limit lower="-1.79769e+308" upper="1.79769e+308" effort="-1.0" velocity="-1.0"/>
  </joint>
  
   <link name="front_right_link">
    <inertial>
      <mass value="1"/>
      <origin xyz="0 0 0" rpy="0 0 0"/>
      <inertia ixx="0.145833" ixy="0" ixz="0" iyy="0.145833" iyz="0" izz="0.125"/>
    </inertial>
    <collision>
      <origin xyz="0 0 0" rpy="0 0 0"/>
      <geometry>
        <cylinder radius="0.04" length="0.03"/>
      </geometry>
    </collision>
    <visual>
      <origin xyz="0 0 0" rpy="0 0 0"/>
      <geometry>
        <cylinder radius="0.04" length="0.03"/>
      </geometry>
    </visual>
  </link>
  
  
  <joint name="front_left_joint" type="revolute">
    <parent link="chassy_link"/>
    <child link="front_left_link"/>
    <origin xyz="-0.09187 -0.09418 -0.015" rpy="1.5708 0     0"/>
    <axis xyz="0 0 1"/>
    <limit lower="-1.79769e+308" upper="1.79769e+308" effort="-1.0" velocity="-1.0"/>
  </joint>
  
  <link name="front_left_link">
    <inertial>
      <mass value="1"/>
      <origin xyz="0 0 0" rpy="0 0 0"/>
      <inertia ixx="0.145833" ixy="0" ixz="0" iyy="0.145833" iyz="0" izz="0.125"/>
    </inertial>
    <collision>
      <origin xyz="0 0 0" rpy="0 0 0"/>
      <geometry>
        <cylinder radius="0.04" length="0.03"/>
      </geometry>
    </collision>
    <visual>
      <origin xyz="0 0 0" rpy="0 0 0"/>
      <geometry>
        <cylinder radius="0.04" length="0.03"/>
      </geometry>
    </visual>
  </link>
  
  
  <joint name="lidar_joint" type="fixed">
    <parent link="chassy_link"/>
    <child link="lidar_link"/>
    <origin xyz="-0.08374  0.00097  0.055" rpy="0 0 0"/>
    <axis xyz="0 0 0"/>
    <limit lower="0" upper="0" effort="0" velocity="0"/>
  </joint>
  
  <link name="lidar_link">
    <inertial>
      <mass value="1"/>
      <origin xyz="0 0 0" rpy="0 0 0"/>
      <inertia ixx="0.145833" ixy="0" ixz="0" iyy="0.145833" iyz="0" izz="0.125"/>
    </inertial>
    <collision>
      <origin xyz="0 0 0" rpy="0 0 0"/>
      <geometry>
        <cylinder radius="0.05" length="0.05"/>
      </geometry>
    </collision>
    <visual>
      <origin xyz="0 0 0" rpy="0 0 0"/>
      <geometry>
        <cylinder radius="0.05" length="0.05"/>
      </geometry>
    </visual>
  </link>
  
  
  <link name="chassy_link">
    <inertial>
      <mass value="1"/>
      <origin xyz="0 0 0" rpy="0 0 0"/>
      <inertia ixx="0.166667" ixy="0" ixz="0" iyy="0.166667" iyz="0" izz="0.166667"/>
    </inertial>
    <collision>
      <origin xyz="-0.01153 -0.0009   0.005" rpy="1.5708 0     1.5708"/>
      <geometry>
        <box size="0.15 0.05 0.25"/>
      </geometry>
    </collision>
    <visual>
      <origin xyz="-0.01153 -0.0009   0.005" rpy="1.5708 0     1.5708"/>
      <geometry>
        <box size="0.15 0.05 0.25"/>
      </geometry>
    </visual>
  </link>
  
</robot>
