<?xml version="1.0" ?>
<robot name="bfl_13" xmlns:xacro="http://ros.org/wiki/xacro">
  <xacro:include filename="$(find dharmendra_model)/gazebo/bfl_13/bfl_13.gazebo"/>
  <joint name="bfl_13__link_0_JOINT_0_0" type="fixed">
    <parent link="bfl_13__link_0"/>
    <child link="bfl_13__link_0_0"/>
    <origin xyz="-0.08272  0.00202  0.09503" rpy="-1.5708  0      1.5708"/>
    <axis xyz="0 0 0"/>
    <limit lower="0" upper="0" effort="0" velocity="0"/>
  </joint>
  <joint name="bfl_13__link_0_JOINT_0" type="revolute">
    <parent link="bfl_13__link_0"/>
    <child link="bfl_13__link_1"/>
    <origin xyz="0.06435 -0.09418 -0.015" rpy="1.5708 0     0"/>
    <axis xyz="0 0 1"/>
    <limit lower="-1.79769e+308" upper="1.79769e+308" effort="-1.0" velocity="-1.0"/>
  </joint>
  <joint name="bfl_13__link_0_JOINT_1" type="revolute">
    <parent link="bfl_13__link_0"/>
    <child link="bfl_13__link_1_clone_0"/>
    <origin xyz="0.06435  0.09414 -0.015" rpy="1.5708 0     0"/>
    <axis xyz="0 0 1"/>
    <limit lower="-1.79769e+308" upper="1.79769e+308" effort="-1.0" velocity="-1.0"/>
  </joint>
  <joint name="bfl_13__link_0_JOINT_2" type="revolute">
    <parent link="bfl_13__link_0"/>
    <child link="bfl_13__link_1_clone_1"/>
    <origin xyz="-0.09187  0.09414 -0.015" rpy="1.5708 0     0"/>
    <axis xyz="0 0 1"/>
    <limit lower="-1.79769e+308" upper="1.79769e+308" effort="-1.0" velocity="-1.0"/>
  </joint>
  <joint name="bfl_13__link_0_JOINT_3" type="revolute">
    <parent link="bfl_13__link_0"/>
    <child link="bfl_13__link_1_clone"/>
    <origin xyz="-0.09187 -0.09418 -0.015" rpy="1.5708 0     0"/>
    <axis xyz="0 0 1"/>
    <limit lower="-1.79769e+308" upper="1.79769e+308" effort="-1.0" velocity="-1.0"/>
  </joint>
  <joint name="bfl_13__link_0_JOINT_4" type="fixed">
    <parent link="bfl_13__link_0"/>
    <child link="bfl_13__link_2"/>
    <origin xyz="-0.08374  0.00097  0.055" rpy="0 0 0"/>
    <axis xyz="0 0 0"/>
    <limit lower="0" upper="0" effort="0" velocity="0"/>
  </joint>
  <link name="bfl_13__link_0">
    <inertial>
      <mass value="1"/>
      <origin xyz="0 0 0" rpy="0 0 0"/>
      <inertia ixx="0.166667" ixy="0" ixz="0" iyy="0.166667" iyz="0" izz="0.166667"/>
    </inertial>
    <collision>
      <origin xyz="-0.01153 -0.0009   0.005" rpy="1.5708 0     1.5708"/>
      <geometry>
        <box size="0.15 0.05 0.25"/>
      </geometry>
    </collision>
    <visual>
      <origin xyz="-0.01153 -0.0009   0.005" rpy="1.5708 0     1.5708"/>
      <geometry>
        <box size="0.15 0.05 0.25"/>
      </geometry>
    </visual>
  </link>
  <link name="bfl_13__link_0_0">
    <inertial>
      <mass value="1"/>
      <origin xyz="0 0 0" rpy="0 0 0"/>
      <inertia ixx="0.166667" ixy="0" ixz="0" iyy="0.166667" iyz="0" izz="0.166667"/>
    </inertial>
    <collision>
      <origin xyz="0 0 0" rpy="0 0 0"/>
      <geometry>
        <box size="0.03 0.03 0.07071"/>
      </geometry>
    </collision>
    <visual>
      <origin xyz="0 0 0" rpy="0 0 0"/>
      <geometry>
        <box size="0.03 0.03 0.07071"/>
      </geometry>
    </visual>
  </link>
  <link name="bfl_13__link_1">
    <inertial>
      <mass value="1"/>
      <origin xyz="0 0 0" rpy="0 0 0"/>
      <inertia ixx="0.145833" ixy="0" ixz="0" iyy="0.145833" iyz="0" izz="0.125"/>
    </inertial>
    <collision>
      <origin xyz="0 0 0" rpy="0 0 0"/>
      <geometry>
        <cylinder radius="0.04" length="0.03"/>
      </geometry>
    </collision>
    <visual>
      <origin xyz="0 0 0" rpy="0 0 0"/>
      <geometry>
        <cylinder radius="0.04" length="0.03"/>
      </geometry>
    </visual>
  </link>
  <link name="bfl_13__link_1_clone">
    <inertial>
      <mass value="1"/>
      <origin xyz="0 0 0" rpy="0 0 0"/>
      <inertia ixx="0.145833" ixy="0" ixz="0" iyy="0.145833" iyz="0" izz="0.125"/>
    </inertial>
    <collision>
      <origin xyz="0 0 0" rpy="0 0 0"/>
      <geometry>
        <cylinder radius="0.04" length="0.03"/>
      </geometry>
    </collision>
    <visual>
      <origin xyz="0 0 0" rpy="0 0 0"/>
      <geometry>
        <cylinder radius="0.04" length="0.03"/>
      </geometry>
    </visual>
  </link>
  <link name="bfl_13__link_1_clone_0">
    <inertial>
      <mass value="1"/>
      <origin xyz="0 0 0" rpy="0 0 0"/>
      <inertia ixx="0.145833" ixy="0" ixz="0" iyy="0.145833" iyz="0" izz="0.125"/>
    </inertial>
    <collision>
      <origin xyz="0 0 0" rpy="0 0 0"/>
      <geometry>
        <cylinder radius="0.04" length="0.03"/>
      </geometry>
    </collision>
    <visual>
      <origin xyz="0 0 0" rpy="0 0 0"/>
      <geometry>
        <cylinder radius="0.04" length="0.03"/>
      </geometry>
    </visual>
  </link>
  <link name="bfl_13__link_1_clone_1">
    <inertial>
      <mass value="1"/>
      <origin xyz="0 0 0" rpy="0 0 0"/>
      <inertia ixx="0.145833" ixy="0" ixz="0" iyy="0.145833" iyz="0" izz="0.125"/>
    </inertial>
    <collision>
      <origin xyz="0 0 0" rpy="0 0 0"/>
      <geometry>
        <cylinder radius="0.04" length="0.03"/>
      </geometry>
    </collision>
    <visual>
      <origin xyz="0 0 0" rpy="0 0 0"/>
      <geometry>
        <cylinder radius="0.04" length="0.03"/>
      </geometry>
    </visual>
  </link>
  <link name="bfl_13__link_2">
    <inertial>
      <mass value="1"/>
      <origin xyz="0 0 0" rpy="0 0 0"/>
      <inertia ixx="0.145833" ixy="0" ixz="0" iyy="0.145833" iyz="0" izz="0.125"/>
    </inertial>
    <collision>
      <origin xyz="0 0 0" rpy="0 0 0"/>
      <geometry>
        <cylinder radius="0.05" length="0.05"/>
      </geometry>
    </collision>
    <visual>
      <origin xyz="0 0 0" rpy="0 0 0"/>
      <geometry>
        <cylinder radius="0.05" length="0.05"/>
      </geometry>
    </visual>
  </link>
</robot>
